[Fri Aug 07 06:25:02.198895 2020] [mpm_event:notice] [pid 1991:tid 139843265846208] AH00489: Apache/2.4.29 (Ubuntu) OpenSSL/1.1.1 mod_wsgi/4.5.17 Python/3.6 configured -- resuming normal operations
[Fri Aug 07 06:25:02.198916 2020] [core:notice] [pid 1991:tid 139843265846208] AH00094: Command line: '/usr/sbin/apache2'
[Fri Aug 07 06:45:32.891365 2020] [mpm_event:notice] [pid 1991:tid 139843265846208] AH00491: caught SIGTERM, shutting down
[Fri Aug 07 06:45:32.966223 2020] [mpm_event:notice] [pid 3191:tid 139874166164416] AH00489: Apache/2.4.29 (Ubuntu) OpenSSL/1.1.1 mod_wsgi/4.5.17 Python/3.6 configured -- resuming normal operations
[Fri Aug 07 06:45:32.966300 2020] [core:notice] [pid 3191:tid 139874166164416] AH00094: Command line: '/usr/sbin/apache2'
[Fri Aug 07 06:45:47.003337 2020] [wsgi:error] [pid 3195:tid 139873881134848] [client 102.69.147.165:52146] mod_wsgi (pid=3195): Target WSGI script '/var/www/pronovserver/pronovserver.wsgi' cannot be loaded as Python module.
[Fri Aug 07 06:45:47.003418 2020] [wsgi:error] [pid 3195:tid 139873881134848] [client 102.69.147.165:52146] mod_wsgi (pid=3195): Exception occurred processing WSGI script '/var/www/pronovserver/pronovserver.wsgi'.
[Fri Aug 07 06:45:47.004692 2020] [wsgi:error] [pid 3195:tid 139873881134848] [client 102.69.147.165:52146] Traceback (most recent call last):
[Fri Aug 07 06:45:47.004732 2020] [wsgi:error] [pid 3195:tid 139873881134848] [client 102.69.147.165:52146]   File "/var/www/pronovserver/ops/connector/connector.py", line 4, in evcon
[Fri Aug 07 06:45:47.004737 2020] [wsgi:error] [pid 3195:tid 139873881134848] [client 102.69.147.165:52146]     con=psycopg2.connect(database='retail',user='pronov',password='f10aeb05',host='localhost',port='5432')
[Fri Aug 07 06:45:47.004745 2020] [wsgi:error] [pid 3195:tid 139873881134848] [client 102.69.147.165:52146]   File "/usr/local/lib/python3.6/dist-packages/psycopg2/__init__.py", line 126, in connect
[Fri Aug 07 06:45:47.004749 2020] [wsgi:error] [pid 3195:tid 139873881134848] [client 102.69.147.165:52146]     conn = _connect(dsn, connection_factory=connection_factory, **kwasync)
[Fri Aug 07 06:45:47.004769 2020] [wsgi:error] [pid 3195:tid 139873881134848] [client 102.69.147.165:52146] psycopg2.OperationalError: FATAL:  database "retail" does not exist
[Fri Aug 07 06:45:47.004773 2020] [wsgi:error] [pid 3195:tid 139873881134848] [client 102.69.147.165:52146] 
[Fri Aug 07 06:45:47.004782 2020] [wsgi:error] [pid 3195:tid 139873881134848] [client 102.69.147.165:52146] 
[Fri Aug 07 06:45:47.004785 2020] [wsgi:error] [pid 3195:tid 139873881134848] [client 102.69.147.165:52146] During handling of the above exception, another exception occurred:
[Fri Aug 07 06:45:47.004788 2020] [wsgi:error] [pid 3195:tid 139873881134848] [client 102.69.147.165:52146] 
[Fri Aug 07 06:45:47.004795 2020] [wsgi:error] [pid 3195:tid 139873881134848] [client 102.69.147.165:52146] Traceback (most recent call last):
[Fri Aug 07 06:45:47.004832 2020] [wsgi:error] [pid 3195:tid 139873881134848] [client 102.69.147.165:52146]   File "/var/www/pronovserver/pronovserver.wsgi", line 7, in <module>
[Fri Aug 07 06:45:47.004836 2020] [wsgi:error] [pid 3195:tid 139873881134848] [client 102.69.147.165:52146]     from __init__ import app as application
[Fri Aug 07 06:45:47.004843 2020] [wsgi:error] [pid 3195:tid 139873881134848] [client 102.69.147.165:52146]   File "/var/www/pronovserver/__init__.py", line 11, in <module>
[Fri Aug 07 06:45:47.004846 2020] [wsgi:error] [pid 3195:tid 139873881134848] [client 102.69.147.165:52146]     from ops.members.members import RevokedToken,EntryException
[Fri Aug 07 06:45:47.004853 2020] [wsgi:error] [pid 3195:tid 139873881134848] [client 102.69.147.165:52146]   File "/var/www/pronovserver/ops/__init__.py", line 1, in <module>
[Fri Aug 07 06:45:47.004856 2020] [wsgi:error] [pid 3195:tid 139873881134848] [client 102.69.147.165:52146]     from .helpers.functions import CurrencyHelper,textualize_datetime,humanize_date,timestamp_now,timestamp_forever
[Fri Aug 07 06:45:47.004863 2020] [wsgi:error] [pid 3195:tid 139873881134848] [client 102.69.147.165:52146]   File "/var/www/pronovserver/ops/helpers/functions.py", line 16, in <module>
[Fri Aug 07 06:45:47.004873 2020] [wsgi:error] [pid 3195:tid 139873881134848] [client 102.69.147.165:52146]     con,cursor=evcon()
[Fri Aug 07 06:45:47.004880 2020] [wsgi:error] [pid 3195:tid 139873881134848] [client 102.69.147.165:52146]   File "/var/www/pronovserver/ops/connector/connector.py", line 8, in evcon
[Fri Aug 07 06:45:47.004883 2020] [wsgi:error] [pid 3195:tid 139873881134848] [client 102.69.147.165:52146]     raise Exception('Connection Error {}'.format(str(e).strip()))
[Fri Aug 07 06:45:47.004898 2020] [wsgi:error] [pid 3195:tid 139873881134848] [client 102.69.147.165:52146] Exception: Connection Error FATAL:  database "retail" does not exist
[Fri Aug 07 06:46:38.623295 2020] [mpm_event:notice] [pid 3191:tid 139874166164416] AH00491: caught SIGTERM, shutting down
[Fri Aug 07 06:46:38.710242 2020] [mpm_event:notice] [pid 3309:tid 140117867686848] AH00489: Apache/2.4.29 (Ubuntu) OpenSSL/1.1.1 mod_wsgi/4.5.17 Python/3.6 configured -- resuming normal operations
[Fri Aug 07 06:46:38.710405 2020] [core:notice] [pid 3309:tid 140117867686848] AH00094: Command line: '/usr/sbin/apache2'
[Fri Aug 07 06:46:41.747766 2020] [wsgi:error] [pid 3313:tid 140117620528896] [client 102.69.147.165:52150] mod_wsgi (pid=3313): Target WSGI script '/var/www/pronovserver/pronovserver.wsgi' cannot be loaded as Python module.
[Fri Aug 07 06:46:41.747878 2020] [wsgi:error] [pid 3313:tid 140117620528896] [client 102.69.147.165:52150] mod_wsgi (pid=3313): Exception occurred processing WSGI script '/var/www/pronovserver/pronovserver.wsgi'.
[Fri Aug 07 06:46:41.748840 2020] [wsgi:error] [pid 3313:tid 140117620528896] [client 102.69.147.165:52150] Traceback (most recent call last):
[Fri Aug 07 06:46:41.748879 2020] [wsgi:error] [pid 3313:tid 140117620528896] [client 102.69.147.165:52150]   File "/var/www/pronovserver/ops/connector/connector.py", line 4, in evcon
[Fri Aug 07 06:46:41.748884 2020] [wsgi:error] [pid 3313:tid 140117620528896] [client 102.69.147.165:52150]     con=psycopg2.connect(database='retail',user='pronov',password='f10aeb05',host='localhost',port='5432')
[Fri Aug 07 06:46:41.748892 2020] [wsgi:error] [pid 3313:tid 140117620528896] [client 102.69.147.165:52150]   File "/usr/local/lib/python3.6/dist-packages/psycopg2/__init__.py", line 126, in connect
[Fri Aug 07 06:46:41.748896 2020] [wsgi:error] [pid 3313:tid 140117620528896] [client 102.69.147.165:52150]     conn = _connect(dsn, connection_factory=connection_factory, **kwasync)
[Fri Aug 07 06:46:41.748918 2020] [wsgi:error] [pid 3313:tid 140117620528896] [client 102.69.147.165:52150] psycopg2.OperationalError: FATAL:  database "retail" does not exist
[Fri Aug 07 06:46:41.748922 2020] [wsgi:error] [pid 3313:tid 140117620528896] [client 102.69.147.165:52150] 
[Fri Aug 07 06:46:41.748931 2020] [wsgi:error] [pid 3313:tid 140117620528896] [client 102.69.147.165:52150] 
[Fri Aug 07 06:46:41.748935 2020] [wsgi:error] [pid 3313:tid 140117620528896] [client 102.69.147.165:52150] During handling of the above exception, another exception occurred:
[Fri Aug 07 06:46:41.748938 2020] [wsgi:error] [pid 3313:tid 140117620528896] [client 102.69.147.165:52150] 
[Fri Aug 07 06:46:41.748945 2020] [wsgi:error] [pid 3313:tid 140117620528896] [client 102.69.147.165:52150] Traceback (most recent call last):
[Fri Aug 07 06:46:41.748981 2020] [wsgi:error] [pid 3313:tid 140117620528896] [client 102.69.147.165:52150]   File "/var/www/pronovserver/pronovserver.wsgi", line 7, in <module>
[Fri Aug 07 06:46:41.748986 2020] [wsgi:error] [pid 3313:tid 140117620528896] [client 102.69.147.165:52150]     from __init__ import app as application
[Fri Aug 07 06:46:41.748993 2020] [wsgi:error] [pid 3313:tid 140117620528896] [client 102.69.147.165:52150]   File "/var/www/pronovserver/__init__.py", line 11, in <module>
[Fri Aug 07 06:46:41.748996 2020] [wsgi:error] [pid 3313:tid 140117620528896] [client 102.69.147.165:52150]     from ops.members.members import RevokedToken,EntryException
[Fri Aug 07 06:46:41.749003 2020] [wsgi:error] [pid 3313:tid 140117620528896] [client 102.69.147.165:52150]   File "/var/www/pronovserver/ops/__init__.py", line 1, in <module>
[Fri Aug 07 06:46:41.749022 2020] [wsgi:error] [pid 3313:tid 140117620528896] [client 102.69.147.165:52150]     from .helpers.functions import CurrencyHelper,textualize_datetime,humanize_date,timestamp_now,timestamp_forever
[Fri Aug 07 06:46:41.749029 2020] [wsgi:error] [pid 3313:tid 140117620528896] [client 102.69.147.165:52150]   File "/var/www/pronovserver/ops/helpers/functions.py", line 16, in <module>
[Fri Aug 07 06:46:41.749032 2020] [wsgi:error] [pid 3313:tid 140117620528896] [client 102.69.147.165:52150]     con,cursor=evcon()
[Fri Aug 07 06:46:41.749038 2020] [wsgi:error] [pid 3313:tid 140117620528896] [client 102.69.147.165:52150]   File "/var/www/pronovserver/ops/connector/connector.py", line 8, in evcon
[Fri Aug 07 06:46:41.749041 2020] [wsgi:error] [pid 3313:tid 140117620528896] [client 102.69.147.165:52150]     raise Exception('Connection Error {}'.format(str(e).strip()))
[Fri Aug 07 06:46:41.749056 2020] [wsgi:error] [pid 3313:tid 140117620528896] [client 102.69.147.165:52150] Exception: Connection Error FATAL:  database "retail" does not exist
